# 4. 异常处理
```
try{
    Code to try;
    Throw an exception with a throw statement or from method if necessary;
    More code to try;
}
catch(type ex){
    Code to process the exception;
}
```
异常处理将检测错误从处理错误中分离出来。
```java
import java.util.Scanner;
public class QuatientWithMethod{
    public static int quotient(int num1, int num2){
        if(num2 ==)
            throw new ArithmeticException("Divisor cannot be zero");
        return num1/num2;            
    }
    public static void main(String[] args){
        Scanner input = new Scanner(System.in);
        System.out.print("Enter two intergers: ");
        int num1 = input.nextInt();
        int num2 = input.nextInt();

        try{
            int result = quotient(num1,num2);
            System.out.println(num1 + " /" + num2 + " is " + result);
        }
        catch(ArithmeticException ex){
            System.out.println("Exception: an integer cannot" 
                +"be dicided by zero");            
        }

        System.out.println("Excution continues...");
    }
}
```
## 异常类型
```
- Object-- Throwable-- Exceprion-- ClassNotFoundException
                     |            |- IOException
                     |            |- RuntiomeException-------- ArithmeticException
                     |            |- ...                    |- NullPointerException
                     |                                      |- IndexOutOfBoundsException
                     |                                      |- IllegalArgumentException
                     |                                      |- ...
                     - Error----|- LinageError
                                |- VirtualMachineError
                                |- ...
```
Error: 系统错误，
Exception: 由程序和外部环境引起的错误，可以捕获及处理。
Runtime exception: 由程序设计错误引起。

注意，现在java没有抛出整数上溢和下溢的异常。

## 声明异常
方法抛出的异常需要在方法头中显式声明。  
``` public void myMethod() throws IOException, Exception2```
## 抛出异常
检测到异常后，创建一个异常实例，并抛出他。  
``` throw new IllegalArgumentException("Wrong argument")```

## 捕获异常
```
try{
    statements;
}
catch(Exception1 exVar1){
    handler for exception1;
}
catch(Exception2 exVar2){
    handler for exception2;
}
```
## 获取异常信息
```
java.lang.Throwable
+getMessage():String
+toString(): String
+printStackTrace(): void
+getStackTrace(): StackTraceElement[]
```
## finally
```java
try{}
catch(TheException ex){}
finally{}
```
任何情况下finally语句都会执行，及时前面有一个return语句。
例如文件操作时文件关闭语句放在finally内。

## 重新抛出异常
如果异常处理器没有处理某个异常，可以重新抛出异常
```
try{}
catch(TheException ex){
    perform opertions before exits;
    throw ex;
}
```
## 创建自定义异常
尽量使用java提供的异常类。
```java
public class InvalidRadiusException extends Exception{
    private double radius;
    public InvalidRadiusException(double radius){
        super("Invalid radius"+radius);
        this.radius = radius;
    }
}
```

## 断言Assertion
断言是一种调试方式，使用assert关键字实现，断言失败时抛出AssertionError，程序结束退出。断言不能用于可恢复的程序错误，只应该用于开发和测试阶段。例如
```java
public static void main(String[] args){
    double x = Math.abs(-12.3);
    assert x>=0 : "x must >=0";    //判断x>=0为false,断言失败，抛出AssertionError
    System.out.println(x);
}
```
