8.1 错误处理
8.1.1 try
try:
    print('try...')
    r = 10/0
    print('result: ', r)
except ZeroDivisionError as e:
    print('except:', e)
finally:
    print('finally...')
print('END')

执行try语句，如果出错，直接跳转到except,如果有finally，则执行finally
可以有多个except捕获不同类型错误
如果没有错误，可以在except后加else语句块
8.1.2 logging
logging，将错误信息记录到日志文件中

采用VaulueError定义错误类型，如
class FooError(ValueError):
    pass
8.1.3 with
一些任务需要先处理，最后进行清理工作，如
file=open('foo.txt')
try:
    data=file.read()
finally:
    file.close()
可以用with as 简单的表示
with open('foo.txt') as file:
    data=file.read()

with 所求值的对象必须有一个enter()方法，一个exit()方法


8.2 调试

8.2.1 assert 
当判断式为True时，继续执行，否则提示错误
def foo(s):
    n = int(s)
    assert n != 0, 'n is zero!'
    return 10/n

def main():
    foo('0')
8.2.2 logging
输出错误到文件
import logging

s = '0'
n = int(s)
logging.info('n = %d', %n)
print(10/n)

8.3 单元测试
unittest模块实现单元测试

import unittest
from mydict import Dict
class TestDict(unittest.TestCase):
    def test_init(self):
        d = Dict(a = 1, b = 'test')
        self.assertEqual(d.a, 1)
        self.assertEqual(d.b, 'test')
        slef.assertTrue(isinstance(d, dict))

    def test_key(self):
        d = Dict()
        d.['key'] = 'value'
        self.assertEqual(d.key, 'value')

编写单元测试时，需要编写一个测试类，从unittest.TestCase继承
以test开头的才会被执行

运行单元测试
在mydict_test.py的最后增加下面代码
if __name__=='__main__':
    unittest.main()

8.4 文档测试
python内置的文档测试模块doctest可以提取注释中的代码并执行测试
